Workbook

Sheet Hoja3
A1: EMPRESA | B1: ALGADI
A3: Etiquetas de fila | B3: Suma de COSTE TOTAL
A4: CORRETURNOS/RAPPELS | B4: -19437.937 | C4: =+VLOOKUP(A4,#REF!,2,) -> #REF!
A5: COL. VEDRUNA CARABANCHEL | B5: -15405.305 | C5: =+VLOOKUP(A5,#REF!,2,) -> #REF!
A6: COL. SAG. CORAZONES MARTIN HEROS | B6: -8125.2855 | C6: =+VLOOKUP(A6,#REF!,2,) -> #REF!
A7: COLEGIO NTRA SRA BUEN CONSEJO | B7: -7030.9953 | C7: =+VLOOKUP(A7,#REF!,2,) -> #REF!
A8: COLEGIO JESUS MAESTRO | B8: -5853.1845 | C8: =+VLOOKUP(A8,#REF!,2,) -> #REF!
A9: COLEGIO AGUSTINIANO | B9: -5026.6597 | C9: =+VLOOKUP(A9,#REF!,2,) -> #REF!
A10: COLEGIO MAYOR ALCALA | B10: -4959.0878 | C10: =+VLOOKUP(A10,#REF!,2,) -> #REF!
A11: COL. SAN AGUSTIN -LOS NEGRALES | B11: -4523.8566 | C11: =+VLOOKUP(A11,#REF!,2,) -> #REF!
A12: COL. SAGRADA. FAMILIA-PINTO | B12: -4443.2338 | C12: =+VLOOKUP(A12,#REF!,2,) -> #REF!
A13: CLARETIANOS COLMENAR SEMINARIO | B13: -3866.7947 | C13: =+VLOOKUP(A13,#REF!,2,) -> #REF!
A14: COLEGIO SAGRADA FAMILIA | B14: -3145.688 | C14: =+VLOOKUP(A14,#REF!,2,) -> #REF!
A15: C.M.U. SAN AGUSTIN | B15: -2968.875 | C15: =+VLOOKUP(A15,#REF!,2,) -> #REF!
... A93: Total general | B93: -144389.17 | C93: =+VLOOKUP(A93,#REF!,2,) -> #REF!

Sheet Hoja4
A1: EMPRESA | B1: ALGADI
A3: Etiquetas de fila | B3: Suma de COSTE TOTAL
A4: ACADE | B4: 826.97667 | C4: =+VLOOKUP(A4,#REF!,2,) -> #REF!
A5: BELIVE RESIDENCIA SAGRADO CORAZON | B5: 139.70172 | C5: =+VLOOKUP(A5,#REF!,2,) -> #REF!
A6: BREWSTER MADRID | B6: 1405.9478 | C6: =+VLOOKUP(A6,#REF!,2,) -> #REF!
A7: BREWSTER MADRID CAMPUS LA MORALEJA | B7: 188.6885
A8: C. IRLANDESAS CASTILLEJA | B8: 1413.1845 | C8: =+VLOOKUP(A8,#REF!,2,) -> #REF!
A9: C.M.STA.MARIA DEL PINO | B9: 1098.4837 | C9: =+VLOOKUP(A9,#REF!,2,) -> #REF!
A10: C.M.U. JAIME DEL AMO | B10: 8252.116 | C10: =+VLOOKUP(A10,#REF!,2,) -> #REF!
A11: C.M.U. SAN AGUSTIN | B11: 2660.7735 | C11: =+VLOOKUP(A11,#REF!,2,) -> #REF!
A12: C.P. CONCEPCIONISTAS - BELISANA | B12: 422.24 | C12: =+VLOOKUP(A12,#REF!,2,) -> #REF!
A13: C.P. PP. AGUSTINOS "PROV. S. JUAN SAHAGUN" | B13: 3041.8829 | C13: =+VLOOKUP(A13,#REF!,2,) -> #REF!
A14: C.P. PP. REPARADORES - BALBINA VALVERDE | B14: 1363.419 | C14: =+VLOOKUP(A14,#REF!,2,) -> #REF!
A15: C.P. TERCIARIOS CAPUCHINOS | B15: 72.5725 | C15: =+VLOOKUP(A15,#REF!,2,) -> #REF!
A16: C.STA TERESA DE JESÚS EL VEDAT | B16: 513.94525 | C16: =+VLOOKUP(A16,#REF!,2,) -> #REF!
A17: C.VIRGEN DEL CARMEN | B17: 2077.4838 | C17: =+VLOOKUP(A17,#REF!,2,) -> #REF!
A18: CASA DE EJERCICIOS SAN JOSE | B18: 392.32622 | C18: =+VLOOKUP(A18,#REF!,2,) -> #REF!
A19: CASA GENERAL MM. CONCEPCIONISTAS | B19: 105.56 | C19: =+VLOOKUP(A19,#REF!,2,) -> #REF!
... A54: COLEGIO JESUS MAESTRO | B54: 225.6345 | C54: =+VLOOKUP(A54,#REF!,2,) -> #REF!
A55: COLEGIO LUX MUNDI | B55: 769.2685
A56: COLEGIO MAYOR ALCALA | B56: 3440.192 | C56: =+VLOOKUP(A56,#REF!,2,) -> #REF!
A57: COLEGIO MAYOR CESAR CARLOS | B57: 5982.1384 | C57: =+VLOOKUP(A57,#REF!,2,) -> #REF!
A58: COLEGIO MM. CONCEPCIONISTAS BURGOS | B58: 430.81675 | C58: =+VLOOKUP(A58,#REF!,2,) -> #REF!
A59: COLEGIO N. S. DE LA PAZ - CANTABRIA | B59: 79.17 | C59: =+VLOOKUP(A59,#REF!,2,) -> #REF!
A60: COLEGIO NTRA SRA BUEN CONSEJO | B60: 4338.2521 | C60: =+VLOOKUP(A60,#REF!,2,) -> #REF!
A61: COLEGIO PADRE DEHON | B61: 413.66325 | C61: =+VLOOKUP(A61,#REF!,2,) -> #REF!
A62: COLEGIO RAFAELA YBARRA | B62: 1231.755 | C62: =+VLOOKUP(A62,#REF!,2,) -> #REF!
A63: COLEGIO RAIMUNDO LULIO | B63: 292.929 | C63: =+VLOOKUP(A63,#REF!,2,) -> #REF!
A64: COLEGIO SAGRADA FAMILIA | B64: 4683.974 | C64: =+VLOOKUP(A64,#REF!,2,) -> #REF!
A65: COLEGIO SAN HERMENEGILDO | B65: 587.83725 | C65: =+VLOOKUP(A65,#REF!,2,) -> #REF!
A66: COLEGIO SANTA RITA | B66: 941.14832 | C66: =+VLOOKUP(A66,#REF!,2,) -> #REF!
A67: COLEGIO TERESIANAS GANDUXER | B67: 1774.7803 | C67: =+VLOOKUP(A67,#REF!,2,) -> #REF!
... A96: VEMARE, S.L | B96: 1419.45 | C96: =+VLOOKUP(A96,#REF!,2,) -> #REF!
A97: Total general | B97: 144002.11 | C97: =+SUM(C4:C96) -> #REF! | D97: =+GETPIVOTDATA("COSTE TOTAL",$A$3)-C97 -> #REF!

Sheet Hoja5
A1: EMPRESA | B1: ALGADI
A3: Etiquetas de fila | B3: Suma de COSTE TOTAL
A4: ACADE | B4: 826.97667 | C4: =+VLOOKUP(A4,[1]Hoja1!$A$4:$B$97,2,) -> 826.97667 | D4: =+B4-C4 -> 0
A5: BELIVE RESIDENCIA SAGRADO CORAZON | B5: 139.70172 | C5: =+VLOOKUP(A5,[1]Hoja1!$A$4:$B$97,2,) -> 139.70172 | D5: =+B5-C5 -> 0
A6: BREWSTER MADRID | B6: 1405.9478 | C6: =+VLOOKUP(A6,[1]Hoja1!$A$4:$B$97,2,) -> 1405.9478 | D6: =+B6-C6 -> 0
A7: BREWSTER MADRID CAMPUS LA MORALEJA | B7: 188.6885 | C7: =+VLOOKUP(A7,[1]Hoja1!$A$4:$B$97,2,) -> 188.6885 | D7: =+B7-C7 -> 0
A8: C. IRLANDESAS CASTILLEJA | B8: 1413.1845 | C8: =+VLOOKUP(A8,[1]Hoja1!$A$4:$B$97,2,) -> 1413.1845 | D8: =+B8-C8 -> 0
A9: C.M.STA.MARIA DEL PINO | B9: 1098.4837 | C9: =+VLOOKUP(A9,[1]Hoja1!$A$4:$B$97,2,) -> 1098.4837 | D9: =+B9-C9 -> 0
A10: C.M.U. JAIME DEL AMO | B10: 8252.116 | C10: =+VLOOKUP(A10,[1]Hoja1!$A$4:$B$97,2,) -> 8252.116 | D10: =+B10-C10 -> 0
A11: C.M.U. SAN AGUSTIN | B11: 2660.7735 | C11: =+VLOOKUP(A11,[1]Hoja1!$A$4:$B$97,2,) -> 2660.7735 | D11: =+B11-C11 -> 0
A12: C.P. CONCEPCIONISTAS - BELISANA | B12: 422.24 | C12: =+VLOOKUP(A12,[1]Hoja1!$A$4:$B$97,2,) -> 422.24 | D12: =+B12-C12 -> 0
A13: C.P. PP. AGUSTINOS "PROV. S. JUAN SAHAGUN" | B13: 3041.8829 | C13: =+VLOOKUP(A13,[1]Hoja1!$A$4:$B$97,2,) -> 3041.8829 | D13: =+B13-C13 -> 0
A14: C.P. PP. REPARADORES - BALBINA VALVERDE | B14: 1363.419 | C14: =+VLOOKUP(A14,[1]Hoja1!$A$4:$B$97,2,) -> 1363.419 | D14: =+B14-C14 -> 0
A15: C.P. TERCIARIOS CAPUCHINOS | B15: 72.5725 | C15: =+VLOOKUP(A15,[1]Hoja1!$A$4:$B$97,2,) -> 72.5725 | D15: =+B15-C15 -> 0
... A97: Total general | B97: 144002.11 | C97: =+VLOOKUP(A97,[1]Hoja1!$A$4:$B$97,2,) -> 143571.3 | D97: =+B97-C97 -> 430.81675

Sheet Incidencias
D1: Campos Obligatorios | M1: Campos automáticos | P1: Campos Obligatorios | X1: Campos automáticos | AA1: Campos Obligatorios | AC1: Campos automáticos
D2: No se pueden quedar estos campos en blanco | J2: DESTINO | P2: INCIDENCIA | S2: NOCTURNIDAD | V2: TRASLADO | AH2: Origen | AN2: Destino | AQ2: NOCTURNIDAD | BD2: ORIGEN | BV2: DESTINO
A3: Fecha envio | B3: Fecha baja | C3: Nº de días vacaciones a pagar | D3: Jefe de Operaciones | E3: Mes imputació nómina | F3: Facturable | G3: Servicio | H3: Motivo | I3: Trabajador | J3: Empresa Destino | K3: Código Crown Destino | L3: control | M3: Centro Destino | N3: CAMPO DE ATENCION | O3: Categoría | P3: Cuantia | Q3: Precio | R3: TOTAL | S3: Cuantía | T3: Precio | U3: TOTAL | V3: HORAS | W3: TOTAL COSTE | X3: Empresa Origen | Y3: Código Crown Origen | Z3: Centro Origen | AA3: Fecha | AB3: Observaciones | AD3: 70/71 - Festivos Total | AE3: 72 - IncentivosTotal | AF3: 73 - Plus sustitución Total | AG3: 74 - Plus nocturnidad Total | AH3: Número empresa Origen | AI3: Número empleado | AJ3: Sección | AK3: Coste Hora | AL3: Convenio | AM3: Categoria | AN3: EMPRESA | AO3: SECCION | AQ3: 99100165012016 | AR3: 28009435011996 | AS3: 99010825011997 | BD3: EMPRESA | BE3: TIPO NOMINA | BF3: MES | BG3: Centro | BH3: Centro preferente | BI3: Denom. Centro prefe | BJ3: Trabajador | BK3: Contrato | BL3: Categoría | BM3: Jornada | BN3: R | BO3: L | BP3: TOTAL | BQ3: dias | BR3: COSTE TOTAL | BV3: EMPRESA | BW3: TIPO NOMINA | BX3: MES | BY3: Centro | BZ3: Centro preferente | CA3: Denom. Centro prefe | CB3: Incidencia | CC3: Contrato | CD3: Categoría | CE3: Jornada | CF3: R | CG3: L | CH3: TOTAL | CI3: dias | CJ3: COSTE TOTAL
D4: 945 | E4: 9-SEPTIEMBRE | F4: NO | G4: 010 Restauración | H4: Permiso retribuido | I4: AGUIRRE NUÑEZ, ADELAIDA | J4: ALGADI | K4: 110021 | L4: =IF(W4>0,IF(OR(E4="",F4="",G4="",H4="",I4="",J4="",K4=""),"faltan datos","ok")," ") -> ok | M4: =IFERROR(VLOOKUP(K4,Centros!$E$2:$G$340,2,FALSE)," ") -> COLEGIO FUNDACION CALDEIRO | N4: =IF(J4=" "," ",IF(J4=X4," ","Emp Orig/dest. Distinta")) | O4: =IFERROR(VLOOKUP($I4,Trabajadores!$C$3:$AF$1684,19,FALSE)," ") -> Cociner@ | P4: 35.6 | Q4: 9 | R4: =+P4*Q4 -> 320.4 | T4: =IF(AL4="99100165012016",AQ4,IF(AL4="28009435011996",AR4,IF(AL4="99010825011997",AS4))) -> 1.7437656 | U4: =IF(T4="no corresponde",0,+S4*T4) -> 0 | W4: =+V4*AK4+((+R4+U4)*1.3195) -> 422.7678 | X4: =IFERROR(VLOOKUP($I4,Trabajadores!$C$2:$AS$1684,42,FALSE)," ") -> ALGADI | Y4: =IFERROR(VLOOKUP($I4,Trabajadores!$C$2:$AS$1684,40,FALSE)," ") -> 340084 | Z4: =IFERROR(VLOOKUP(Y4,Centros!$X$2:$Y$228,2,FALSE)," ") -> MISIONERAS CLARETIANAS J.HERNANDEZ | AA4: Septiembre´25 | AB4: Excedencia Johanna Villegas (limpieza Caldeiro) | AC4: =IFERROR(VLOOKUP(H4,Centros!$AI$2:$AN$10,6,FALSE),0) -> 72 | AD4: =IF(AC4=70,R4,0) -> 0 | AE4: =IF(AC4=72,R4,0) -> 320.4 | AF4: =IF(AC4=73,+R4,0) -> 0 | AG4: =+U4 -> 0 | AH4: =IFERROR(VLOOKUP($I4,Trabajadores!$C$3:$AT$1684,44,FALSE),0) -> 19228 | AI4: =IFERROR(VLOOKUP($I4,Trabajadores!$C$3:$AT$1684,2,FALSE),0) -> 1683 | AJ4: =IFERROR(VLOOKUP($I4,Trabajadores!$C$3:$AY$1270,21,FALSE),0) -> 70 | AK4: =IFERROR(VLOOKUP($I4,Trabajadores!$C$3:$AN$1684,38,FALSE),0) -> 5.79375 | AL4: =IFERROR(VLOOKUP($I4,Trabajadores!$C$3:$AN$1684,28,FALSE),0) -> 99100165012016 | AM4: =IFERROR(VLOOKUP($I4,Trabajadores!$C$3:$AN$1684,19,FALSE),0) -> Cociner@ | AN4: =IFERROR(IF($J4="algadi",VLOOKUP($K4,Centros!$AB$2:$AD$142,2,FALSE),VLOOKUP($K4,Centros!$AB$143:$AD$282,2,FALSE)),0) -> 19228 | AO4: =IFERROR(IF($J4="algadi",VLOOKUP($K4,Centros!$AB$2:$AD$142,3,FALSE),VLOOKUP($K4,Centros!$AB$143:$AD$222,3,FALSE)),0) -> 20 | AQ4: =IFERROR(VLOOKUP($AM4,Centros!$AR$2:$AS$405,2,FALSE),0) -> 1.7437656 | AR4: =IFERROR(VLOOKUP($AM4,Centros!$AZ$2:$BA$6,2,FALSE),0) -> 2.32225 | AS4: =IFERROR(VLOOKUP($AM4,Centros!$BE$2:$BF$6,2,FALSE),0) -> 0 | BD4: =+X4 -> ALGADI | BE4: INCIDENCIA | BF4: =+E4 -> 9-SEPTIEMBRE | BG4: =+Y4 -> 340084 | BH4: =VLOOKUP(Y4,Hoja1!$A$2:$O$599,14,FALSE) -> 340084 | BI4: =VLOOKUP(BH4,Hoja1!$A$2:$O$599,2,FALSE) -> MISIONERAS CLARETIANAS J.HERNANDEZ | BJ4: =+I4 -> AGUIRRE NUÑEZ, ADELAIDA | BK4: =VLOOKUP(BJ4,Trabajadores!$C$3:$AN$3285,14,FALSE) -> 100 | BL4: =VLOOKUP($BJ4,Trabajadores!$C$3:$AN$3285,19,FALSE) -> Cociner@ | BM4: =VLOOKUP($BJ4,Trabajadores!$C$3:$AN$3285,16,FALSE) -> 100 | BN4: =IF($G4="010 Restauración",100%,0%) -> 1 | BO4: =IF($G4="020 Limpieza",100%,0%) -> 0 | BP4: =+BN4+BO4 -> 1 | BR4: =-W4 -> -422.7678 | BV4: =+J4 -> ALGADI | BW4: INCIDENCIA | BX4: =+E4 -> 9-SEPTIEMBRE | BY4: =+K4 -> 110021 | BZ4: =VLOOKUP(BY4,Hoja1!$A$2:$O$599,14,FALSE) -> 110021 | CA4: =VLOOKUP(BZ4,Hoja1!$A$2:$O$599,2,FALSE) -> COLEGIO FUNDACION CALDEIRO | CB4: =+H4 -> Permiso retribuido | CC4: 888 | CD4: =+BW4 -> INCIDENCIA | CJ4: =+W4 -> 422.7678
D5: 945 | E5: 9-SEPTIEMBRE | F5: NO | G5: 010 Restauración | H5: Festivos y Fines de Semana | I5: ALONSO ALONSO, ANGEL LUIS | J5: ALGADI | K5: 510005 | L5: =IF(W5>0,IF(OR(E5="",F5="",G5="",H5="",I5="",J5="",K5=""),"faltan datos","ok")," ") -> ok | M5: =IFERROR(VLOOKUP(K5,Centros!$E$2:$G$340,2,FALSE)," ") -> C.P. TERCIARIOS CAPUCHINOS | N5: =IF(J5=" "," ",IF(J5=X5," ","Emp Orig/dest. Distinta")) | O5: =IFERROR(VLOOKUP($I5,Trabajadores!$C$3:$AF$1684,19,FALSE)," ") -> h Cociner@ | P5: 1 | Q5: 55 | R5: =+P5*Q5 -> 55 | T5: =IF(AL5="99100165012016",AQ5,IF(AL5="28009435011996",AR5,IF(AL5="99010825011997",AS5))) -> 1.7437656 | U5: =IF(T5="no corresponde",0,+S5*T5) -> 0 | W5: =+V5*AK5+((+R5+U5)*1.3195) -> 72.5725 | X5: =IFERROR(VLOOKUP($I5,Trabajadores!$C$2:$AS$1684,42,FALSE)," ") -> ALGADI | Y5: =IFERROR(VLOOKUP($I5,Trabajadores!$C$2:$AS$1684,40,FALSE)," ") -> 110216 | Z5: =IFERROR(VLOOKUP(Y5,Centros!$X$2:$Y$228,2,FALSE)," ") -> COL. MATER INMACULATA | AA5: 45913 | AB5: Sábado Belisana | AC5: =IFERROR(VLOOKUP(H5,Centros!$AI$2:$AN$10,6,FALSE),0) -> 70 | AD5: =IF(AC5=70,R5,0) -> 55 | AE5: =IF(AC5=72,R5,0) -> 0 | AF5: =IF(AC5=73,+R5,0) -> 0 | AG5: =+U5 -> 0 | AH5: =IFERROR(VLOOKUP($I5,Trabajadores!$C$3:$AT$1684,44,FALSE),0) -> 19228 | AI5: =IFERROR(VLOOKUP($I5,Trabajadores!$C$3:$AT$1684,2,FALSE),0) -> 1334 | AJ5: =IFERROR(VLOOKUP($I5,Trabajadores!$C$3:$AY$1270,21,FALSE),0) -> 107 | AK5: =IFERROR(VLOOKUP($I5,Trabajadores!$C$3:$AN$1684,38,FALSE),0) -> 11.40625 | AL5: =IFERROR(VLOOKUP($I5,Trabajadores!$C$3:$AN$1684,28,FALSE),0) -> 99100165012016 | AM5: =IFERROR(VLOOKUP($I5,Trabajadores!$C$3:$AN$1684,19,FALSE),0) -> h Cociner@ | AN5: =IFERROR(IF($J5="algadi",VLOOKUP($K5,Centros!$AB$2:$AD$142,2,FALSE),VLOOKUP($K5,Centros!$AB$143:$AD$282,2,FALSE)),0) -> 5027 | AO5: =IFERROR(IF($J5="algadi",VLOOKUP($K5,Centros!$AB$2:$AD$142,3,FALSE),VLOOKUP($K5,Centros!$AB$143:$AD$222,3,FALSE)),0) -> 51 | AQ5: =IFERROR(VLOOKUP($AM5,Centros!$AR$2:$AS$405,2,FALSE),0) -> 1.7437656 | AR5: =IFERROR(VLOOKUP($AM5,Centros!$AZ$2:$BA$6,2,FALSE),0) -> 0 | AS5: =IFERROR(VLOOKUP($AM5,Centros!$BE$2:$BF$6,2,FALSE),0) -> 0 | BD5: =+X5 -> ALGADI | BE5: INCIDENCIA | BF5: =+E5 -> 9-SEPTIEMBRE | BG5: =+Y5 -> 110216 | BH5: =VLOOKUP(Y5,Hoja1!$A$2:$O$599,14,FALSE) -> 110216 | BI5: =VLOOKUP(BH5,Hoja1!$A$2:$O$599,2,FALSE) -> COL. MATER INMACULATA | BJ5: =+I5 -> ALONSO ALONSO, ANGEL LUIS | BK5: =VLOOKUP(BJ5,Trabajadores!$C$3:$AN$3285,14,FALSE) -> 300 | BL5: =VLOOKUP($BJ5,Trabajadores!$C$3:$AN$3285,19,FALSE) -> h Cociner@ | BM5: =VLOOKUP($BJ5,Trabajadores!$C$3:$AN$3285,16,FALSE) -> 100 | BN5: =IF($G5="010 Restauración",100%,0%) -> 1 | BO5: =IF($G5="020 Limpieza",100%,0%) -> 0 | BP5: =+BN5+BO5 -> 1 | BR5: =-W5 -> -72.5725 | BV5: =+J5 -> ALGADI | BW5: INCIDENCIA | BX5: =+E5 -> 9-SEPTIEMBRE | BY5: =+K5 -> 510005 | BZ5: =VLOOKUP(BY5,Hoja1!$A$2:$O$599,14,FALSE) -> 510005 | CA5: =VLOOKUP(BZ5,Hoja1!$A$2:$O$599,2,FALSE) -> C.P. TERCIARIOS CAPUCHINOS | CB5: =+H5 -> Festivos y Fines de Semana | CC5: 888 | CD5: =+BW5 -> INCIDENCIA | CJ5: =+W5 -> 72.5725
D6: 945 | E6: 9-SEPTIEMBRE | F6: NO | G6: 010 Restauración | H6: Festivos y Fines de Semana | I6: ALONSO ALONSO, ANGEL LUIS | J6: ALGADI | K6: 510006 | L6: =IF(W6>0,IF(OR(E6="",F6="",G6="",H6="",I6="",J6="",K6=""),"faltan datos","ok")," ") -> ok | M6: =IFERROR(VLOOKUP(K6,Centros!$E$2:$G$340,2,FALSE)," ") -> C.P. CONCEPCIONISTAS - BELISANA | N6: =IF(J6=" "," ",IF(J6=X6," ","Emp Orig/dest. Distinta")) | O6: =IFERROR(VLOOKUP($I6,Trabajadores!$C$3:$AF$1684,19,FALSE)," ") -> h Cociner@ | P6: 1 | Q6: 80 | R6: =+P6*Q6 -> 80 | T6: =IF(AL6="99100165012016",AQ6,IF(AL6="28009435011996",AR6,IF(AL6="99010825011997",AS6))) -> 1.7437656 | U6: =IF(T6="no corresponde",0,+S6*T6) -> 0 | W6: =+V6*AK6+((+R6+U6)*1.3195) -> 105.56 | X6: =IFERROR(VLOOKUP($I6,Trabajadores!$C$2:$AS$1684,42,FALSE)," ") -> ALGADI | Y6: =IFERROR(VLOOKUP($I6,Trabajadores!$C$2:$AS$1684,40,FALSE)," ") -> 110216 | Z6: =IFERROR(VLOOKUP(Y6,Centros!$X$2:$Y$228,2,FALSE)," ") -> COL. MATER INMACULATA | AA6: 45920 | AB6: Sábado Belisana | AC6: =IFERROR(VLOOKUP(H6,Centros!$AI$2:$AN$10,6,FALSE),0) -> 70 | AD6: =IF(AC6=70,R6,0) -> 80 | AE6: =IF(AC6=72,R6,0) -> 0 | AF6: =IF(AC6=73,+R6,0) -> 0 | AG6: =+U6 -> 0 | AH6: =IFERROR(VLOOKUP($I6,Trabajadores!$C$3:$AT$1684,44,FALSE),0) -> 19228 | AI6: =IFERROR(VLOOKUP($I6,Trabajadores!$C$3:$AT$1684,2,FALSE),0) -> 1334 | AJ6: =IFERROR(VLOOKUP($I6,Trabajadores!$C$3:$AY$1270,21,FALSE),0) -> 107 | AK6: =IFERROR(VLOOKUP($I6,Trabajadores!$C$3:$AN$1684,38,FALSE),0) -> 11.40625 | AL6: =IFERROR(VLOOKUP($I6,Trabajadores!$C$3:$AN$1684,28,FALSE),0) -> 99100165012016 | AM6: =IFERROR(VLOOKUP($I6,Trabajadores!$C$3:$AN$1684,19,FALSE),0) -> h Cociner@ | AN6: =IFERROR(IF($J6="algadi",VLOOKUP($K6,Centros!$AB$2:$AD$142,2,FALSE),VLOOKUP($K6,Centros!$AB$143:$AD$282,2,FALSE)),0) -> 5027 | AO6: =IFERROR(IF($J6="algadi",VLOOKUP($K6,Centros!$AB$2:$AD$142,3,FALSE),VLOOKUP($K6,Centros!$AB$143:$AD$222,3,FALSE)),0) -> 70 | AQ6: =IFERROR(VLOOKUP($AM6,Centros!$AR$2:$AS$405,2,FALSE),0) -> 1.7437656 | AR6: =IFERROR(VLOOKUP($AM6,Centros!$AZ$2:$BA$6,2,FALSE),0) -> 0 | AS6: =IFERROR(VLOOKUP($AM6,Centros!$BE$2:$BF$6,2,FALSE),0) -> 0 | BD6: =+X6 -> ALGADI | BE6: INCIDENCIA | BF6: =+E6 -> 9-SEPTIEMBRE | BG6: =+Y6 -> 110216 | BH6: =VLOOKUP(Y6,Hoja1!$A$2:$O$599,14,FALSE) -> 110216 | BI6: =VLOOKUP(BH6,Hoja1!$A$2:$O$599,2,FALSE) -> COL. MATER INMACULATA | BJ6: =+I6 -> ALONSO ALONSO, ANGEL LUIS | BK6: =VLOOKUP(BJ6,Trabajadores!$C$3:$AN$3285,14,FALSE) -> 300 | BL6: =VLOOKUP($BJ6,Trabajadores!$C$3:$AN$3285,19,FALSE) -> h Cociner@ | BM6: =VLOOKUP($BJ6,Trabajadores!$C$3:$AN$3285,16,FALSE) -> 100 | BN6: =IF($G6="010 Restauración",100%,0%) -> 1 | BO6: =IF($G6="020 Limpieza",100%,0%) -> 0 | BP6: =+BN6+BO6 -> 1 | BR6: =-W6 -> -105.56 | BV6: =+J6 -> ALGADI | BW6: INCIDENCIA | BX6: =+E6 -> 9-SEPTIEMBRE | BY6: =+K6 -> 510006 | BZ6: =VLOOKUP(BY6,Hoja1!$A$2:$O$599,14,FALSE) -> 510006 | CA6: =VLOOKUP(BZ6,Hoja1!$A$2:$O$599,2,FALSE) -> C.P. CONCEPCIONISTAS - BELISANA | CB6: =+H6 -> Festivos y Fines de Semana | CC6: 888 | CD6: =+BW6 -> INCIDENCIA | CJ6: =+W6 -> 105.56
D7: 945 | E7: 9-SEPTIEMBRE | F7: NO | G7: 010 Restauración | H7: Festivos y Fines de Semana | I7: ALONSO ALONSO, ANGEL LUIS | J7: ALGADI | K7: 510015 | L7: =IF(W7>0,IF(OR(E7="",F7="",G7="",H7="",I7="",J7="",K7=""),"faltan datos","ok")," ") -> ok | M7: =IFERROR(VLOOKUP(K7,Centros!$E$2:$G$340,2,FALSE)," ") -> CASA GENERAL MM. CONCEPCIONISTAS | N7: =IF(J7=" "," ",IF(J7=X7," ","Emp Orig/dest. Distinta")) | O7: =IFERROR(VLOOKUP($I7,Trabajadores!$C$3:$AF$1684,19,FALSE)," ") -> h Cociner@ | P7: 1 | Q7: 80 | R7: =+P7*Q7 -> 80 | T7: =IF(AL7="99100165012016",AQ7,IF(AL7="28009435011996",AR7,IF(AL7="99010825011997",AS7))) -> 1.7437656 | U7: =IF(T7="no corresponde",0,+S7*T7) -> 0 | W7: =+V7*AK7+((+R7+U7)*1.3195) -> 105.56 | X7: =IFERROR(VLOOKUP($I7,Trabajadores!$C$2:$AS$1684,42,FALSE)," ") -> ALGADI | Y7: =IFERROR(VLOOKUP($I7,Trabajadores!$C$2:$AS$1684,40,FALSE)," ") -> 110216 | Z7: =IFERROR(VLOOKUP(Y7,Centros!$X$2:$Y$228,2,FALSE)," ") -> COL. MATER INMACULATA | AA7: 45892 | AB7: Elvia no puede hacer el sábado en Sanchez Guerrero y hay grupo | AC7: =IFERROR(VLOOKUP(H7,Centros!$AI$2:$AN$10,6,FALSE),0) -> 70 | AD7: =IF(AC7=70,R7,0) -> 80 | AE7: =IF(AC7=72,R7,0) -> 0 | AF7: =IF(AC7=73,+R7,0) -> 0 | AG7: =+U7 -> 0 | AH7: =IFERROR(VLOOKUP($I7,Trabajadores!$C$3:$AT$1684,44,FALSE),0) -> 19228 | AI7: =IFERROR(VLOOKUP($I7,Trabajadores!$C$3:$AT$1684,2,FALSE),0) -> 1334 | AJ7: =IFERROR(VLOOKUP($I7,Trabajadores!$C$3:$AY$1270,21,FALSE),0) -> 107 | AK7: =IFERROR(VLOOKUP($I7,Trabajadores!$C$3:$AN$1684,38,FALSE),0) -> 11.40625 | AL7: =IFERROR(VLOOKUP($I7,Trabajadores!$C$3:$AN$1684,28,FALSE),0) -> 99100165012016 | AM7: =IFERROR(VLOOKUP($I7,Trabajadores!$C$3:$AN$1684,19,FALSE),0) -> h Cociner@ | AN7: =IFERROR(IF($J7="algadi",VLOOKUP($K7,Centros!$AB$2:$AD$142,2,FALSE),VLOOKUP($K7,Centros!$AB$143:$AD$282,2,FALSE)),0) -> 19228 | AO7: =IFERROR(IF($J7="algadi",VLOOKUP($K7,Centros!$AB$2:$AD$142,3,FALSE),VLOOKUP($K7,Centros!$AB$143:$AD$222,3,FALSE)),0) -> 33 | AQ7: =IFERROR(VLOOKUP($AM7,Centros!$AR$2:$AS$405,2,FALSE),0) -> 1.7437656 | AR7: =IFERROR(VLOOKUP($AM7,Centros!$AZ$2:$BA$6,2,FALSE),0) -> 0 | AS7: =IFERROR(VLOOKUP($AM7,Centros!$BE$2:$BF$6,2,FALSE),0) -> 0 | BD7: =+X7 -> ALGADI | BE7: INCIDENCIA | BF7: =+E7 -> 9-SEPTIEMBRE | BG7: =+Y7 -> 110216 | BH7: =VLOOKUP(Y7,Hoja1!$A$2:$O$599,14,FALSE) -> 110216 | BI7: =VLOOKUP(BH7,Hoja1!$A$2:$O$599,2,FALSE) -> COL. MATER INMACULATA | BJ7: =+I7 -> ALONSO ALONSO, ANGEL LUIS | BK7: =VLOOKUP(BJ7,Trabajadores!$C$3:$AN$3285,14,FALSE) -> 300 | BL7: =VLOOKUP($BJ7,Trabajadores!$C$3:$AN$3285,19,FALSE) -> h Cociner@ | BM7: =VLOOKUP($BJ7,Trabajadores!$C$3:$AN$3285,16,FALSE) -> 100 | BN7: =IF($G7="010 Restauración",100%,0%) -> 1 | BO7: =IF($G7="020 Limpieza",100%,0%) -> 0 | BP7: =+BN7+BO7 -> 1 | BR7: =-W7 -> -105.56 | BV7: =+J7 -> ALGADI | BW7: INCIDENCIA | BX7: =+E7 -> 9-SEPTIEMBRE | BY7: =+K7 -> 510015 | BZ7: =VLOOKUP(BY7,Hoja1!$A$2:$O$599,14,FALSE) -> 510015 | CA7: =VLOOKUP(BZ7,Hoja1!$A$2:$O$599,2,FALSE) -> CASA GENERAL MM. CONCEPCIONISTAS | CB7: =+H7 -> Festivos y Fines de Semana | CC7: 888 | CD7: =+BW7 -> INCIDENCIA | CJ7: =+W7 -> 105.56
D8: 945 | E8: 9-SEPTIEMBRE | F8: NO | G8: 020 Limpieza | H8: Permiso retribuido | I8: ALZATE CARDENAS, MELISSA | J8: ALGADI | K8: 110082 | L8: =IF(W8>0,IF(OR(E8="",F8="",G8="",H8="",I8="",J8="",K8=""),"faltan datos","ok")," ") -> ok | M8: =IFERROR(VLOOKUP(K8,Centros!$E$2:$G$340,2,FALSE)," ") -> COL. SAN MIGUEL ARCANGEL | N8: =IF(J8=" "," ",IF(J8=X8," ","Emp Orig/dest. Distinta")) | O8: =IFERROR(VLOOKUP($I8,Trabajadores!$C$3:$AF$1684,19,FALSE)," ") -> ASL | P8: 7 | Q8: 9 | R8: =+P8*Q8 -> 63 | T8: =IF(AL8="99100165012016",AQ8,IF(AL8="28009435011996",AR8,IF(AL8="99010825011997",AS8))) -> 1.6367812 | U8: =IF(T8="no corresponde",0,+S8*T8) -> 0 | W8: =+V8*AK8+((+R8+U8)*1.3195) -> 83.1285 | X8: =IFERROR(VLOOKUP($I8,Trabajadores!$C$2:$AS$1684,42,FALSE)," ") -> ALGADI | Y8: =IFERROR(VLOOKUP($I8,Trabajadores!$C$2:$AS$1684,40,FALSE)," ") -> 110082 | Z8: =IFERROR(VLOOKUP(Y8,Centros!$X$2:$Y$228,2,FALSE)," ") -> COL. SAN MIGUEL ARCANGEL | AA8: 19, 22 y 23 sept´25 | AB8: PR de Pilar Fernández (ingreso hermano) | AC8: =IFERROR(VLOOKUP(H8,Centros!$AI$2:$AN$10,6,FALSE),0) -> 72 | AD8: =IF(AC8=70,R8,0) -> 0 | AE8: =IF(AC8=72,R8,0) -> 63 | AF8: =IF(AC8=73,+R8,0) -> 0 | AG8: =+U8 -> 0 | AH8: =IFERROR(VLOOKUP($I8,Trabajadores!$C$3:$AT$1684,44,FALSE),0) -> 19228 | AI8: =IFERROR(VLOOKUP($I8,Trabajadores!$C$3:$AT$1684,2,FALSE),0) -> 1035 | AJ8: =IFERROR(VLOOKUP($I8,Trabajadores!$C$3:$AY$1270,21,FALSE),0) -> 4 | AK8: =IFERROR(VLOOKUP($I8,Trabajadores!$C$3:$AN$1684,38,FALSE),0) -> 7.8 | AL8: =IFERROR(VLOOKUP($I8,Trabajadores!$C$3:$AN$1684,28,FALSE),0) -> 99100165012016 | AM8: =IFERROR(VLOOKUP($I8,Trabajadores!$C$3:$AN$1684,19,FALSE),0) -> ASL | AN8: =IFERROR(IF($J8="algadi",VLOOKUP($K8,Centros!$AB$2:$AD$142,2,FALSE),VLOOKUP($K8,Centros!$AB$143:$AD$282,2,FALSE)),0) -> 19228 | AO8: =IFERROR(IF($J8="algadi",VLOOKUP($K8,Centros!$AB$2:$AD$142,3,FALSE),VLOOKUP($K8,Centros!$AB$143:$AD$222,3,FALSE)),0) -> 4 | AQ8: =IFERROR(VLOOKUP($AM8,Centros!$AR$2:$AS$405,2,FALSE),0) -> 1.6367812 | AR8: =IFERROR(VLOOKUP($AM8,Centros!$AZ$2:$BA$6,2,FALSE),0) -> 0 | AS8: =IFERROR(VLOOKUP($AM8,Centros!$BE$2:$BF$6,2,FALSE),0) -> 2.05 | BD8: =+X8 -> ALGADI | BE8: INCIDENCIA | BF8: =+E8 -> 9-SEPTIEMBRE | BG8: =+Y8 -> 110082 | BH8: =VLOOKUP(Y8,Hoja1!$A$2:$O$599,14,FALSE) -> 110082 | BI8: =VLOOKUP(BH8,Hoja1!$A$2:$O$599,2,FALSE) -> COL. SAN MIGUEL ARCANGEL | BJ8: =+I8 -> ALZATE CARDENAS, MELISSA | BK8: =VLOOKUP(BJ8,Trabajadores!$C$3:$AN$3285,14,FALSE) -> 510 | BL8: =VLOOKUP($BJ8,Trabajadores!$C$3:$AN$3285,19,FALSE) -> ASL | BM8: =VLOOKUP($BJ8,Trabajadores!$C$3:$AN$3285,16,FALSE) -> 50 | BN8: =IF($G8="010 Restauración",100%,0%) -> 0 | BO8: =IF($G8="020 Limpieza",100%,0%) -> 1 | BP8: =+BN8+BO8 -> 1 | BR8: =-W8 -> -83.1285 | BV8: =+J8 -> ALGADI | BW8: INCIDENCIA | BX8: =+E8 -> 9-SEPTIEMBRE | BY8: =+K8 -> 110082 | BZ8: =VLOOKUP(BY8,Hoja1!$A$2:$O$599,14,FALSE) -> 110082 | CA8: =VLOOKUP(BZ8,Hoja1!$A$2:$O$599,2,FALSE) -> COL. SAN MIGUEL ARCANGEL | CB8: =+H8 -> Permiso retribuido | CC8: 888 | CD8: =+BW8 -> INCIDENCIA | CJ8: =+W8 -> 83.1285
D9: 945 | E9: 9-SEPTIEMBRE | F9: SI | G9: 020 Limpieza | H9: Refuerzo | I9: ALZATE CARDENAS, MELISSA | J9: ALGADI | K9: 110082 | L9: =IF(W9>0,IF(OR(E9="",F9="",G9="",H9="",I9="",J9="",K9=""),"faltan datos","ok")," ") -> ok | M9: =IFERROR(VLOOKUP(K9,Centros!$E$2:$G$340,2,FALSE)," ") -> COL. SAN MIGUEL ARCANGEL | N9: =IF(J9=" "," ",IF(J9=X9," ","Emp Orig/dest. Distinta")) | O9: =IFERROR(VLOOKUP($I9,Trabajadores!$C$3:$AF$1684,19,FALSE)," ") -> ASL | P9: 4 | Q9: 9 | R9: =+P9*Q9 -> 36 | T9: =IF(AL9="99100165012016",AQ9,IF(AL9="28009435011996",AR9,IF(AL9="99010825011997",AS9))) -> 1.6367812 | U9: =IF(T9="no corresponde",0,+S9*T9) -> 0 | W9: =+V9*AK9+((+R9+U9)*1.3195) -> 47.502 | X9: =IFERROR(VLOOKUP($I9,Trabajadores!$C$2:$AS$1684,42,FALSE)," ") -> ALGADI | Y9: =IFERROR(VLOOKUP($I9,Trabajadores!$C$2:$AS$1684,40,FALSE)," ") -> 110082 | Z9: =IFERROR(VLOOKUP(Y9,Centros!$X$2:$Y$228,2,FALSE)," ") -> COL. SAN MIGUEL ARCANGEL | AA9: 4, 5 y 6 Septiembre´25 | AB9: LIMPIEZA TEATRO | AC9: =IFERROR(VLOOKUP(H9,Centros!$AI$2:$AN$10,6,FALSE),0) -> 72 | AD9: =IF(AC9=70,R9,0) -> 0 | AE9: =IF(AC9=72,R9,0) -> 36 | AF9: =IF(AC9=73,+R9,0) -> 0 | AG9: =+U9 -> 0 | AH9: =IFERROR(VLOOKUP($I9,Trabajadores!$C$3:$AT$1684,44,FALSE),0) -> 19228 | AI9: =IFERROR(VLOOKUP($I9,Trabajadores!$C$3:$AT$1684,2,FALSE),0) -> 1035 | AJ9: =IFERROR(VLOOKUP($I9,Trabajadores!$C$3:$AY$1270,21,FALSE),0) -> 4 | AK9: =IFERROR(VLOOKUP($I9,Trabajadores!$C$3:$AN$1684,38,FALSE),0) -> 7.8 | AL9: =IFERROR(VLOOKUP($I9,Trabajadores!$C$3:$AN$1684,28,FALSE),0) -> 99100165012016 | AM9: =IFERROR(VLOOKUP($I9,Trabajadores!$C$3:$AN$1684,19,FALSE),0) -> ASL | AN9: =IFERROR(IF($J9="algadi",VLOOKUP($K9,Centros!$AB$2:$AD$142,2,FALSE),VLOOKUP($K9,Centros!$AB$143:$AD$282,2,FALSE)),0) -> 19228 | AO9: =IFERROR(IF($J9="algadi",VLOOKUP($K9,Centros!$AB$2:$AD$142,3,FALSE),VLOOKUP($K9,Centros!$AB$143:$AD$222,3,FALSE)),0) -> 4 | AQ9: =IFERROR(VLOOKUP($AM9,Centros!$AR$2:$AS$405,2,FALSE),0) -> 1.6367812 | AR9: =IFERROR(VLOOKUP($AM9,Centros!$AZ$2:$BA$6,2,FALSE),0) -> 0 | AS9: =IFERROR(VLOOKUP($AM9,Centros!$BE$2:$BF$6,2,FALSE),0) -> 2.05 | BD9: =+X9 -> ALGADI | BE9: INCIDENCIA | BF9: =+E9 -> 9-SEPTIEMBRE | BG9: =+Y9 -> 110082 | BH9: =VLOOKUP(Y9,Hoja1!$A$2:$O$599,14,FALSE) -> 110082 | BI9: =VLOOKUP(BH9,Hoja1!$A$2:$O$599,2,FALSE) -> COL. SAN MIGUEL ARCANGEL | BJ9: =+I9 -> ALZATE CARDENAS, MELISSA | BK9: =VLOOKUP(BJ9,Trabajadores!$C$3:$AN$3285,14,FALSE) -> 510 | BL9: =VLOOKUP($BJ9,Trabajadores!$C$3:$AN$3285,19,FALSE) -> ASL | BM9: =VLOOKUP($BJ9,Trabajadores!$C$3:$AN$3285,16,FALSE) -> 50 | BN9: =IF($G9="010 Restauración",100%,0%) -> 0 | BO9: =IF($G9="020 Limpieza",100%,0%) -> 1 | BP9: =+BN9+BO9 -> 1 | BR9: =-W9 -> -47.502 | BV9: =+J9 -> ALGADI | BW9: INCIDENCIA | BX9: =+E9 -> 9-SEPTIEMBRE | BY9: =+K9 -> 110082 | BZ9: =VLOOKUP(BY9,Hoja1!$A$2:$O$599,14,FALSE) -> 110082 | CA9: =VLOOKUP(BZ9,Hoja1!$A$2:$O$599,2,FALSE) -> COL. SAN MIGUEL ARCANGEL | CB9: =+H9 -> Refuerzo | CC9: 888 | CD9: =+BW9 -> INCIDENCIA | CJ9: =+W9 -> 47.502
D10: 945 | E10: 9-SEPTIEMBRE | F10: SI | G10: 020 Limpieza | H10: Refuerzo | I10: ALZATE CARDENAS, MELISSA | J10: ALGADI | K10: 110082 | L10: =IF(W10>0,IF(OR(E10="",F10="",G10="",H10="",I10="",J10="",K10=""),"faltan datos","ok")," ") -> ok | M10: =IFERROR(VLOOKUP(K10,Centros!$E$2:$G$340,2,FALSE)," ") -> COL. SAN MIGUEL ARCANGEL | N10: =IF(J10=" "," ",IF(J10=X10," ","Emp Orig/dest. Distinta")) | O10: =IFERROR(VLOOKUP($I10,Trabajadores!$C$3:$AF$1684,19,FALSE)," ") -> ASL | P10: 16 | Q10: 9 | R10: =+P10*Q10 -> 144 | T10: =IF(AL10="99100165012016",AQ10,IF(AL10="28009435011996",AR10,IF(AL10="99010825011997",AS10))) -> 1.6367812 | U10: =IF(T10="no corresponde",0,+S10*T10) -> 0 | W10: =+V10*AK10+((+R10+U10)*1.3195) -> 190.008 | X10: =IFERROR(VLOOKUP($I10,Trabajadores!$C$2:$AS$1684,42,FALSE)," ") -> ALGADI | Y10: =IFERROR(VLOOKUP($I10,Trabajadores!$C$2:$AS$1684,40,FALSE)," ") -> 110082 | Z10: =IFERROR(VLOOKUP(Y10,Centros!$X$2:$Y$228,2,FALSE)," ") -> COL. SAN MIGUEL ARCANGEL | AA10: Agosto´25 | AB10: Refuerzo por NSPP de Nikole (refuerzo limpieza pedido cliente) | AC10: =IFERROR(VLOOKUP(H10,Centros!$AI$2:$AN$10,6,FALSE),0) -> 72 | AD10: =IF(AC10=70,R10,0) -> 0 | AE10: =IF(AC10=72,R10,0) -> 144 | AF10: =IF(AC10=73,+R10,0) -> 0 | AG10: =+U10 -> 0 | AH10: =IFERROR(VLOOKUP($I10,Trabajadores!$C$3:$AT$1684,44,FALSE),0) -> 19228 | AI10: =IFERROR(VLOOKUP($I10,Trabajadores!$C$3:$AT$1684,2,FALSE),0) -> 1035 | AJ10: =IFERROR(VLOOKUP($I10,Trabajadores!$C$3:$AY$1270,21,FALSE),0) -> 4 | AK10: =IFERROR(VLOOKUP($I10,Trabajadores!$C$3:$AN$1684,38,FALSE),0) -> 7.8 | AL10: =IFERROR(VLOOKUP($I10,Trabajadores!$C$3:$AN$1684,28,FALSE),0) -> 99100165012016 | AM10: =IFERROR(VLOOKUP($I10,Trabajadores!$C$3:$AN$1684,19,FALSE),0) -> ASL | AN10: =IFERROR(IF($J10="algadi",VLOOKUP($K10,Centros!$AB$2:$AD$142,2,FALSE),VLOOKUP($K10,Centros!$AB$143:$AD$282,2,FALSE)),0) -> 19228 | AO10: =IFERROR(IF($J10="algadi",VLOOKUP($K10,Centros!$AB$2:$AD$142,3,FALSE),VLOOKUP($K10,Centros!$AB$143:$AD$222,3,FALSE)),0) -> 4 | AQ10: =IFERROR(VLOOKUP($AM10,Centros!$AR$2:$AS$405,2,FALSE),0) -> 1.6367812 | AR10: =IFERROR(VLOOKUP($AM10,Centros!$AZ$2:$BA$6,2,FALSE),0) -> 0 | AS10: =IFERROR(VLOOKUP($AM10,Centros!$BE$2:$BF$6,2,FALSE),0) -> 2.05 | BD10: =+X10 -> ALGADI | BE10: INCIDENCIA | BF10: =+E10 -> 9-SEPTIEMBRE | BG10: =+Y10 -> 110082 | BH10: =VLOOKUP(Y10,Hoja1!$A$2:$O$599,14,FALSE) -> 110082 | BI10: =VLOOKUP(BH10,Hoja1!$A$2:$O$599,2,FALSE) -> COL. SAN MIGUEL ARCANGEL | BJ10: =+I10 -> ALZATE CARDENAS, MELISSA | BK10: =VLOOKUP(BJ10,Trabajadores!$C$3:$AN$3285,14,FALSE) -> 510 | BL10: =VLOOKUP($BJ10,Trabajadores!$C$3:$AN$3285,19,FALSE) -> ASL | BM10: =VLOOKUP($BJ10,Trabajadores!$C$3:$AN$3285,16,FALSE) -> 50 | BN10: =IF($G10="010 Restauración",100%,0%) -> 0 | BO10: =IF($G10="020 Limpieza",100%,0%) -> 1 | BP10: =+BN10+BO10 -> 1 | BR10: =-W10 -> -190.008 | BV10: =+J10 -> ALGADI | BW10: INCIDENCIA | BX10: =+E10 -> 9-SEPTIEMBRE | BY10: =+K10 -> 110082 | BZ10: =VLOOKUP(BY10,Hoja1!$A$2:$O$599,14,FALSE) -> 110082 | CA10: =VLOOKUP(BZ10,Hoja1!$A$2:$O$599,2,FALSE) -> COL. SAN MIGUEL ARCANGEL | CB10: =+H10 -> Refuerzo | CC10: 888 | CD10: =+BW10 -> INCIDENCIA | CJ10: =+W10 -> 190.008
D11: 945 | E11: 9-SEPTIEMBRE | F11: NO | G11: 010 Restauración | H11: Otros | I11: BELTRE GOMEZ, CARMEN G | J11: ALGADI | K11: 110065 | L11: =IF(W11>0,IF(OR(E11="",F11="",G11="",H11="",I11="",J11="",K11=""),"faltan datos","ok")," ") -> ok | M11: =IFERROR(VLOOKUP(K11,Centros!$E$2:$G$340,2,FALSE)," ") -> COLEGIO SANTA RITA | N11: =IF(J11=" "," ",IF(J11=X11," ","Emp Orig/dest. Distinta")) | O11: =IFERROR(VLOOKUP($I11,Trabajadores!$C$3:$AF$1684,19,FALSE)," ") -> ASL | P11: 11.5 | Q11: 5.76 | R11: =+P11*Q11 -> 66.24 | T11: =IF(AL11="99100165012016",AQ11,IF(AL11="28009435011996",AR11,IF(AL11="99010825011997",AS11))) -> 1.6367812 | U11: =IF(T11="no corresponde",0,+S11*T11) -> 0 | W11: =+V11*AK11+((+R11+U11)*1.3195) -> 87.40368 | X11: =IFERROR(VLOOKUP($I11,Trabajadores!$C$2:$AS$1684,42,FALSE)," ") -> ALGADI | Y11: =IFERROR(VLOOKUP($I11,Trabajadores!$C$2:$AS$1684,40,FALSE)," ") -> 110065 | Z11: =IFERROR(VLOOKUP(Y11,Centros!$X$2:$Y$228,2,FALSE)," ") -> COLEGIO SANTA RITA | AA11: Serp´25 | AB11: 1/2 hora diaria por fuera contrato (SMI) desde el 8-09-25 | AC11: =IFERROR(VLOOKUP(H11,Centros!$AI$2:$AN$10,6,FALSE),0) -> 72 | AD11: =IF(AC11=70,R11,0) -> 0 | AE11: =IF(AC11=72,R11,0) -> 66.24 | AF11: =IF(AC11=73,+R11,0) -> 0 | AG11: =+U11 -> 0 | AH11: =IFERROR(VLOOKUP($I11,Trabajadores!$C$3:$AT$1684,44,FALSE),0) -> 19228 | AI11: =IFERROR(VLOOKUP($I11,Trabajadores!$C$3:$AT$1684,2,FALSE),0) -> 1444 | AJ11: =IFERROR(VLOOKUP($I11,Trabajadores!$C$3:$AY$1270,21,FALSE),0) -> 6 | AK11: =IFERROR(VLOOKUP($I11,Trabajadores!$C$3:$AN$1684,38,FALSE),0) -> 7.7885714 | AL11: =IFERROR(VLOOKUP($I11,Trabajadores!$C$3:$AN$1684,28,FALSE),0) -> 99100165012016 | AM11: =IFERROR(VLOOKUP($I11,Trabajadores!$C$3:$AN$1684,19,FALSE),0) -> ASL | AN11: =IFERROR(IF($J11="algadi",VLOOKUP($K11,Centros!$AB$2:$AD$142,2,FALSE),VLOOKUP($K11,Centros!$AB$143:$AD$282,2,FALSE)),0) -> 5027 | AO11: =IFERROR(IF($J11="algadi",VLOOKUP($K11,Centros!$AB$2:$AD$142,3,FALSE),VLOOKUP($K11,Centros!$AB$143:$AD$222,3,FALSE)),0) -> 33 | AQ11: =IFERROR(VLOOKUP($AM11,Centros!$AR$2:$AS$405,2,FALSE),0) -> 1.6367812 | AR11: =IFERROR(VLOOKUP($AM11,Centros!$AZ$2:$BA$6,2,FALSE),0) -> 0 | AS11: =IFERROR(VLOOKUP($AM11,Centros!$BE$2:$BF$6,2,FALSE),0) -> 2.05 | BD11: =+X11 -> ALGADI | BE11: INCIDENCIA | BF11: =+E11 -> 9-SEPTIEMBRE | BG11: =+Y11 -> 110065 | BH11: =VLOOKUP(Y11,Hoja1!$A$2:$O$599,14,FALSE) -> 110065 | BI11: =VLOOKUP(BH11,Hoja1!$A$2:$O$599,2,FALSE) -> COLEGIO SANTA RITA | BJ11: =+I11 -> BELTRE GOMEZ, CARMEN G | BK11: =VLOOKUP(BJ11,Trabajadores!$C$3:$AN$3285,14,FALSE) -> 300 | BL11: =VLOOKUP($BJ11,Trabajadores!$C$3:$AN$3285,19,FALSE) -> ASL | BM11: =VLOOKUP($BJ11,Trabajadores!$C$3:$AN$3285,16,FALSE) -> 43.75 | BN11: =IF($G11="010 Restauración",100%,0%) -> 1 | BO11: =IF($G11="020 Limpieza",100%,0%) -> 0 | BP11: =+BN11+BO11 -> 1 | BR11: =-W11 -> -87.40368 | BV11: =+J11 -> ALGADI | BW11: INCIDENCIA | BX11: =+E11 -> 9-SEPTIEMBRE | BY11: =+K11 -> 110065 | BZ11: =VLOOKUP(BY11,Hoja1!$A$2:$O$599,14,FALSE) -> 110065 | CA11: =VLOOKUP(BZ11,Hoja1!$A$2:$O$599,2,FALSE) -> COLEGIO SANTA RITA | CB11: =+H11 -> Otros | CC11: 888 | CD11: =+BW11 -> INCIDENCIA | CJ11: =+W11 -> 87.40368
D12: 945 | E12: 9-SEPTIEMBRE | F12: NO | G12: 020 Limpieza | H12: Permiso retribuido | I12: CABELLO CLAJER, ANA BELEN | J12: ALGADI | K12: 110021 | L12: =IF(W12>0,IF(OR(E12="",F12="",G12="",H12="",I12="",J12="",K12=""),"faltan datos","ok")," ") -> ok | M12: =IFERROR(VLOOKUP(K12,Centros!$E$2:$G$340,2,FALSE)," ") -> COLEGIO FUNDACION CALDEIRO | N12: =IF(J12=" "," ",IF(J12=X12," ","Emp Orig/dest. Distinta")) | O12: =IFERROR(VLOOKUP($I12,Trabajadores!$C$3:$AF$1684,19,FALSE)," ") -> ASL | P12: 28.5 | Q12: 9 | R12: =+P12*Q12 -> 256.5 | T12: =IF(AL12="99100165012016",AQ12,IF(AL12="28009435011996",AR12,IF(AL12="99010825011997",AS12))) -> 1.6367812 | U12: =IF(T12="no corresponde",0,+S12*T12) -> 0 | W12: =+V12*AK12+((+R12+U12)*1.3195) -> 338.45175 | X12: =IFERROR(VLOOKUP($I12,Trabajadores!$C$2:$AS$1684,42,FALSE)," ") -> ALGADI | Y12: =IFERROR(VLOOKUP($I12,Trabajadores!$C$2:$AS$1684,40,FALSE)," ") -> 888888 | Z12: =IFERROR(VLOOKUP(Y12,Centros!$X$2:$Y$228,2,FALSE)," ") -> CORRETURNOS/RAPPELS | AA12: 25 la 29 de agosto | AB12: IT LUCIA JIMENEZ | AC12: =IFERROR(VLOOKUP(H12,Centros!$AI$2:$AN$10,6,FALSE),0) -> 72 | AD12: =IF(AC12=70,R12,0) -> 0 | AE12: =IF(AC12=72,R12,0) -> 256.5 | AF12: =IF(AC12=73,+R12,0) -> 0 | AG12: =+U12 -> 0 | AH12: =IFERROR(VLOOKUP($I12,Trabajadores!$C$3:$AT$1684,44,FALSE),0) -> 19228 | AI12: =IFERROR(VLOOKUP($I12,Trabajadores!$C$3:$AT$1684,2,FALSE),0) -> 2107 | AJ12: =IFERROR(VLOOKUP($I12,Trabajadores!$C$3:$AY$1270,21,FALSE),0) -> 55 | AK12: =IFERROR(VLOOKUP($I12,Trabajadores!$C$3:$AN$1684,38,FALSE),0) -> 8.365 | AL12: =IFERROR(VLOOKUP($I12,Trabajadores!$C$3:$AN$1684,28,FALSE),0) -> 99100165012016 | AM12: =IFERROR(VLOOKUP($I12,Trabajadores!$C$3:$AN$1684,19,FALSE),0) -> ASL | AN12: =IFERROR(IF($J12="algadi",VLOOKUP($K12,Centros!$AB$2:$AD$142,2,FALSE),VLOOKUP($K12,Centros!$AB$143:$AD$282,2,FALSE)),0) -> 19228 | AO12: =IFERROR(IF($J12="algadi",VLOOKUP($K12,Centros!$AB$2:$AD$142,3,FALSE),VLOOKUP($K12,Centros!$AB$143:$AD$222,3,FALSE)),0) -> 20 | AQ12: =IFERROR(VLOOKUP($AM12,Centros!$AR$2:$AS$405,2,FALSE),0) -> 1.6367812 | AR12: =IFERROR(VLOOKUP($AM12,Centros!$AZ$2:$BA$6,2,FALSE),0) -> 0 | AS12: =IFERROR(VLOOKUP($AM12,Centros!$BE$2:$BF$6,2,FALSE),0) -> 2.05 | BD12: =+X12 -> ALGADI | BE12: INCIDENCIA | BF12: =+E12 -> 9-SEPTIEMBRE | BG12: =+Y12 -> 888888 | BH12: =VLOOKUP(Y12,Hoja1!$A$2:$O$599,14,FALSE) -> 888888 | BI12: =VLOOKUP(BH12,Hoja1!$A$2:$O$599,2,FALSE) -> CORRETURNOS/RAPPELS | BJ12: =+I12 -> CABELLO CLAJER, ANA BELEN | BK12: =VLOOKUP(BJ12,Trabajadores!$C$3:$AN$3285,14,FALSE) -> 389 | BL12: =VLOOKUP($BJ12,Trabajadores!$C$3:$AN$3285,19,FALSE) -> ASL | BM12: =VLOOKUP($BJ12,Trabajadores!$C$3:$AN$3285,16,FALSE) -> 50 | BN12: =IF($G12="010 Restauración",100%,0%) -> 0 | BO12: =IF($G12="020 Limpieza",100%,0%) -> 1 | BP12: =+BN12+BO12 -> 1 | BR12: =-W12 -> -338.45175 | BV12: =+J12 -> ALGADI | BW12: INCIDENCIA | BX12: =+E12 -> 9-SEPTIEMBRE | BY12: =+K12 -> 110021 | BZ12: =VLOOKUP(BY12,Hoja1!$A$2:$O$599,14,FALSE) -> 110021 | CA12: =VLOOKUP(BZ12,Hoja1!$A$2:$O$599,2,FALSE) -> COLEGIO FUNDACION CALDEIRO | CB12: =+H12 -> Permiso retribuido | CC12: 888 | CD12: =+BW12 -> INCIDENCIA | CJ12: =+W12 -> 338.45175
D13: 945 | E13: 9-SEPTIEMBRE | F13: NO | G13: 010 Restauración | H13: Festivos y Fines de Semana | I13: CANDO ROSERO, LAURA R | J13: ALGADI | K13: 110030 | L13: =IF(W13>0,IF(OR(E13="",F13="",G13="",H13="",I13="",J13="",K13=""),"faltan datos","ok")," ") -> ok | M13: =IFERROR(VLOOKUP(K13,Centros!$E$2:$G$340,2,FALSE)," ") -> COLEGIO INMACULADA | N13: =IF(J13=" "," ",IF(J13=X13," ","Emp Orig/dest. Distinta")) | O13: =IFERROR(VLOOKUP($I13,Trabajadores!$C$3:$AF$1684,19,FALSE)," ") -> h Ay Cocin | P13: 1 | Q13: 82.5 | R13: =+P13*Q13 -> 82.5 | T13: =IF(AL13="99100165012016",AQ13,IF(AL13="28009435011996",AR13,IF(AL13="99010825011997",AS13))) -> 1.6906094 | U13: =IF(T13="no corresponde",0,+S13*T13) -> 0 | W13: =+V13*AK13+((+R13+U13)*1.3195) -> 108.85875 | X13: =IFERROR(VLOOKUP($I13,Trabajadores!$C$2:$AS$1684,42,FALSE)," ") -> ALGADI | Y13: =IFERROR(VLOOKUP($I13,Trabajadores!$C$2:$AS$1684,40,FALSE)," ") -> 110030 | Z13: =IFERROR(VLOOKUP(Y13,Centros!$X$2:$Y$228,2,FALSE)," ") -> COLEGIO INMACULADA | AA13: 45920 | AB13: 1/2 especial y 1/2 ASL | AC13: =IFERROR(VLOOKUP(H13,Centros!$AI$2:$AN$10,6,FALSE),0) -> 70 | AD13: =IF(AC13=70,R13,0) -> 82.5 | AE13: =IF(AC13=72,R13,0) -> 0 | AF13: =IF(AC13=73,+R13,0) -> 0 | AG13: =+U13 -> 0 | AH13: =IFERROR(VLOOKUP($I13,Trabajadores!$C$3:$AT$1684,44,FALSE),0) -> 19228 | AI13: =IFERROR(VLOOKUP($I13,Trabajadores!$C$3:$AT$1684,2,FALSE),0) -> 198 | AJ13: =IFERROR(VLOOKUP($I13,Trabajadores!$C$3:$AY$1270,21,FALSE),0) -> 36 | AK13: =IFERROR(VLOOKUP($I13,Trabajadores!$C$3:$AN$1684,38,FALSE),0) -> 8.45625 | AL13: =IFERROR(VLOOKUP($I13,Trabajadores!$C$3:$AN$1684,28,FALSE),0) -> 99100165012016 | AM13: =IFERROR(VLOOKUP($I13,Trabajadores!$C$3:$AN$1684,19,FALSE),0) -> h Ay Cocin | AN13: =IFERROR(IF($J13="algadi",VLOOKUP($K13,Centros!$AB$2:$AD$142,2,FALSE),VLOOKUP($K13,Centros!$AB$143:$AD$282,2,FALSE)),0) -> 19228 | AO13: =IFERROR(IF($J13="algadi",VLOOKUP($K13,Centros!$AB$2:$AD$142,3,FALSE),VLOOKUP($K13,Centros!$AB$143:$AD$222,3,FALSE)),0) -> 36 | AQ13: =IFERROR(VLOOKUP($AM13,Centros!$AR$2:$AS$405,2,FALSE),0) -> 1.6906094 | AR13: =IFERROR(VLOOKUP($AM13,Centros!$AZ$2:$BA$6,2,FALSE),0) -> 0 | AS13: =IFERROR(VLOOKUP($AM13,Centros!$BE$2:$BF$6,2,FALSE),0) -> 0 | BD13: =+X13 -> ALGADI | BE13: INCIDENCIA | BF13: =+E13 -> 9-SEPTIEMBRE | BG13: =+Y13 -> 110030 | BH13: =VLOOKUP(Y13,Hoja1!$A$2:$O$599,14,FALSE) -> 110030 | BI13: =VLOOKUP(BH13,Hoja1!$A$2:$O$599,2,FALSE) -> COLEGIO INMACULADA | BJ13: =+I13 -> CANDO ROSERO, LAURA R | BK13: =VLOOKUP(BJ13,Trabajadores!$C$3:$AN$3285,14,FALSE) -> 100 | BL13: =VLOOKUP($BJ13,Trabajadores!$C$3:$AN$3285,19,FALSE) -> h Ay Cocin | BM13: =VLOOKUP($BJ13,Trabajadores!$C$3:$AN$3285,16,FALSE) -> 100 | BN13: =IF($G13="010 Restauración",100%,0%) -> 1 | BO13: =IF($G13="020 Limpieza",100%,0%) -> 0 | BP13: =+BN13+BO13 -> 1 | BR13: =-W13 -> -108.85875 | BV13: =+J13 -> ALGADI | BW13: INCIDENCIA | BX13: =+E13 -> 9-SEPTIEMBRE | BY13: =+K13 -> 110030 | BZ13: =VLOOKUP(BY13,Hoja1!$A$2:$O$599,14,FALSE) -> 110030 | CA13: =VLOOKUP(BZ13,Hoja1!$A$2:$O$599,2,FALSE) -> COLEGIO INMACULADA | CB13: =+H13 -> Festivos y Fines de Semana | CC13: 888 | CD13: =+BW13 -> INCIDENCIA | CJ13: =+W13 -> 108.85875
D14: 945 | E14: 9-SEPTIEMBRE | F14: NO | G14: 010 Restauración | H14: Festivos y Fines de Semana | I14: CAÑIZARES SAEZ, DAVID | J14: ALGADI | K14: 510006 | L14: =IF(W14>0,IF(OR(E14="",F14="",G14="",H14="",I14="",J14="",K14=""),"faltan datos","ok")," ") -> ok | M14: =IFERROR(VLOOKUP(K14,Centros!$E$2:$G$340,2,FALSE)," ") -> C.P. CONCEPCIONISTAS - BELISANA | N14: =IF(J14=" "," ",IF(J14=X14," ","Emp Orig/dest. Distinta")) | O14: =IFERROR(VLOOKUP($I14,Trabajadores!$C$3:$AF$1684,19,FALSE)," ") -> Cociner@ | P14: 1 | Q14: 80 | R14: =+P14*Q14 -> 80 | T14: =IF(AL14="99100165012016",AQ14,IF(AL14="28009435011996",AR14,IF(AL14="99010825011997",AS14))) -> 1.7437656 | U14: =IF(T14="no corresponde",0,+S14*T14) -> 0 | W14: =+V14*AK14+((+R14+U14)*1.3195) -> 105.56 | X14: =IFERROR(VLOOKUP($I14,Trabajadores!$C$2:$AS$1684,42,FALSE)," ") -> ALGADI | Y14: =IFERROR(VLOOKUP($I14,Trabajadores!$C$2:$AS$1684,40,FALSE)," ") -> 110807 | Z14: =IFERROR(VLOOKUP(Y14,Centros!$X$2:$Y$228,2,FALSE)," ") -> COLEGIO NTRA SRA BUEN CONSEJO | AA14: 6 sept´25 | AB14: Sábado en Belisana | AC14: =IFERROR(VLOOKUP(H14,Centros!$AI$2:$AN$10,6,FALSE),0) -> 70 | AD14: =IF(AC14=70,R14,0) -> 80 | AE14: =IF(AC14=72,R14,0) -> 0 | AF14: =IF(AC14=73,+R14,0) -> 0 | AG14: =+U14 -> 0 | AH14: =IFERROR(VLOOKUP($I14,Trabajadores!$C$3:$AT$1684,44,FALSE),0) -> 19228 | AI14: =IFERROR(VLOOKUP($I14,Trabajadores!$C$3:$AT$1684,2,FALSE),0) -> 1777 | AJ14: =IFERROR(VLOOKUP($I14,Trabajadores!$C$3:$AY$1270,21,FALSE),0) -> 61 | AK14: =IFERROR(VLOOKUP($I14,Trabajadores!$C$3:$AN$1684,38,FALSE),0) -> 7.60125 | AL14: =IFERROR(VLOOKUP($I14,Trabajadores!$C$3:$AN$1684,28,FALSE),0) -> 99100165012016 | AM14: =IFERROR(VLOOKUP($I14,Trabajadores!$C$3:$AN$1684,19,FALSE),0) -> Cociner@ | AN14: =IFERROR(IF($J14="algadi",VLOOKUP($K14,Centros!$AB$2:$AD$142,2,FALSE),VLOOKUP($K14,Centros!$AB$143:$AD$282,2,FALSE)),0) -> 5027 | AO14: =IFERROR(IF($J14="algadi",VLOOKUP($K14,Centros!$AB$2:$AD$142,3,FALSE),VLOOKUP($K14,Centros!$AB$143:$AD$222,3,FALSE)),0) -> 70 | AQ14: =IFERROR(VLOOKUP($AM14,Centros!$AR$2:$AS$405,2,FALSE),0) -> 1.7437656 | AR14: =IFERROR(VLOOKUP($AM14,Centros!$AZ$2:$BA$6,2,FALSE),0) -> 2.32225 | AS14: =IFERROR(VLOOKUP($AM14,Centros!$BE$2:$BF$6,2,FALSE),0) -> 0 | BD14: =+X14 -> ALGADI | BE14: INCIDENCIA | BF14: =+E14 -> 9-SEPTIEMBRE | BG14: =+Y14 -> 110807 | BH14: =VLOOKUP(Y14,Hoja1!$A$2:$O$599,14,FALSE) -> 110807 | BI14: =VLOOKUP(BH14,Hoja1!$A$2:$O$599,2,FALSE) -> COLEGIO NTRA SRA BUEN CONSEJO | BJ14: =+I14 -> CAÑIZARES SAEZ, DAVID | BK14: =VLOOKUP(BJ14,Trabajadores!$C$3:$AN$3285,14,FALSE) -> 100 | BL14: =VLOOKUP($BJ14,Trabajadores!$C$3:$AN$3285,19,FALSE) -> Cociner@ | BM14: =VLOOKUP($BJ14,Trabajadores!$C$3:$AN$3285,16,FALSE) -> 100 | BN14: =IF($G14="010 Restauración",100%,0%) -> 1 | BO14: =IF($G14="020 Limpieza",100%,0%) -> 0 | BP14: =+BN14+BO14 -> 1 | BR14: =-W14 -> -105.56 | BV14: =+J14 -> ALGADI | BW14: INCIDENCIA | BX14: =+E14 -> 9-SEPTIEMBRE | BY14: =+K14 -> 510006 | BZ14: =VLOOKUP(BY14,Hoja1!$A$2:$O$599,14,FALSE) -> 510006 | CA14: =VLOOKUP(BZ14,Hoja1!$A$2:$O$599,2,FALSE) -> C.P. CONCEPCIONISTAS - BELISANA | CB14: =+H14 -> Festivos y Fines de Semana | CC14: 888 | CD14: =+BW14 -> INCIDENCIA | CJ14: =+W14 -> 105.56
D15: 945 | E15: 9-SEPTIEMBRE | F15: NO | G15: 010 Restauración | H15: Eventos | I15: CARRO GUERRERO, M CARMEN | J15: ALGADI | K15: 110091 | L15: =IF(W15>0,IF(OR(E15="",F15="",G15="",H15="",I15="",J15="",K15=""),"faltan datos","ok")," ") -> ok | M15: =IFERROR(VLOOKUP(K15,Centros!$E$2:$G$340,2,FALSE)," ") -> COLEGIO CLARET -MADRID | N15: =IF(J15=" "," ",IF(J15=X15," ","Emp Orig/dest. Distinta")) | O15: =IFERROR(VLOOKUP($I15,Trabajadores!$C$3:$AF$1684,19,FALSE)," ") -> h ASL | P15: 3 | Q15: 9 | R15: =+P15*Q15 -> 27 | T15: =IF(AL15="99100165012016",AQ15,IF(AL15="28009435011996",AR15,IF(AL15="99010825011997",AS15))) -> 1.6367812 | U15: =IF(T15="no corresponde",0,+S15*T15) -> 0 | W15: =+V15*AK15+((+R15+U15)*1.3195) -> 35.6265 | X15: =IFERROR(VLOOKUP($I15,Trabajadores!$C$2:$AS$1684,42,FALSE)," ") -> ALGADI | Y15: =IFERROR(VLOOKUP($I15,Trabajadores!$C$2:$AS$1684,40,FALSE)," ") -> 110091 | Z15: =IFERROR(VLOOKUP(Y15,Centros!$X$2:$Y$228,2,FALSE)," ") -> COLEGIO CLARET -MADRID | AA15: 45901 | AB15: Desayunos comienzo profesores | AC15: =IFERROR(VLOOKUP(H15,Centros!$AI$2:$AN$10,6,FALSE),0) -> 72 | AD15: =IF(AC15=70,R15,0) -> 0 | AE15: =IF(AC15=72,R15,0) -> 27 | AF15: =IF(AC15=73,+R15,0) -> 0 | AG15: =+U15 -> 0 | AH15: =IFERROR(VLOOKUP($I15,Trabajadores!$C$3:$AT$1684,44,FALSE),0) -> 19228 | AI15: =IFERROR(VLOOKUP($I15,Trabajadores!$C$3:$AT$1684,2,FALSE),0) -> 276 | AJ15: =IFERROR(VLOOKUP($I15,Trabajadores!$C$3:$AY$1270,21,FALSE),0) -> 50 | AK15: =IFERROR(VLOOKUP($I15,Trabajadores!$C$3:$AN$1684,38,FALSE),0) -> 9.47 | AL15: =IFERROR(VLOOKUP($I15,Trabajadores!$C$3:$AN$1684,28,FALSE),0) -> 99100165012016 | AM15: =IFERROR(VLOOKUP($I15,Trabajadores!$C$3:$AN$1684,19,FALSE),0) -> h ASL | AN15: =IFERROR(IF($J15="algadi",VLOOKUP($K15,Centros!$AB$2:$AD$142,2,FALSE),VLOOKUP($K15,Centros!$AB$143:$AD$282,2,FALSE)),0) -> 0 | AO15: =IFERROR(IF($J15="algadi",VLOOKUP($K15,Centros!$AB$2:$AD$142,3,FALSE),VLOOKUP($K15,Centros!$AB$143:$AD$222,3,FALSE)),0) -> 0 | AQ15: =IFERROR(VLOOKUP($AM15,Centros!$AR$2:$AS$405,2,FALSE),0) -> 1.6367812 | AR15: =IFERROR(VLOOKUP($AM15,Centros!$AZ$2:$BA$6,2,FALSE),0) -> 0 | AS15: =IFERROR(VLOOKUP($AM15,Centros!$BE$2:$BF$6,2,FALSE),0) -> 0 | BD15: =+X15 -> ALGADI | BE15: INCIDENCIA | BF15: =+E15 -> 9-SEPTIEMBRE | BG15: =+Y15 -> 110091 | BH15: =VLOOKUP(Y15,Hoja1!$A$2:$O$599,14,FALSE) -> 110091 | BI15: =VLOOKUP(BH15,Hoja1!$A$2:$O$599,2,FALSE) -> COLEGIO CLARET -MADRID | BJ15: =+I15 -> CARRO GUERRERO, M CARMEN | BK15: =VLOOKUP(BJ15,Trabajadores!$C$3:$AN$3285,14,FALSE) -> 300 | BL15: =VLOOKUP($BJ15,Trabajadores!$C$3:$AN$3285,19,FALSE) -> h ASL | BM15: =VLOOKUP($BJ15,Trabajadores!$C$3:$AN$3285,16,FALSE) -> 50 | BN15: =IF($G15="010 Restauración",100%,0%) -> 1 | BO15: =IF($G15="020 Limpieza",100%,0%) -> 0 | BP15: =+BN15+BO15 -> 1 | BR15: =-W15 -> -35.6265 | BV15: =+J15 -> ALGADI | BW15: INCIDENCIA | BX15: =+E15 -> 9-SEPTIEMBRE | BY15: =+K15 -> 110091 | BZ15: =VLOOKUP(BY15,Hoja1!$A$2:$O$599,14,FALSE) -> 110091 | CA15: =VLOOKUP(BZ15,Hoja1!$A$2:$O$599,2,FALSE) -> COLEGIO CLARET -MADRID | CB15: =+H15 -> Eventos | CC15: 888 | CD15: =+BW15 -> INCIDENCIA | CJ15: =+W15 -> 35.6265
D16: 945 | E16: 9-SEPTIEMBRE | F16: NO | G16: 010 Restauración | H16: Permiso retribuido | I16: CARRO GUERRERO, M CARMEN | J16: ALGADI | K16: 110091 | L16: =IF(W16>0,IF(OR(E16="",F16="",G16="",H16="",I16="",J16="",K16=""),"faltan datos","ok")," ") -> ok | M16: =IFERROR(VLOOKUP(K16,Centros!$E$2:$G$340,2,FALSE)," ") -> COLEGIO CLARET -MADRID | N16: =IF(J16=" "," ",IF(J16=X16," ","Emp Orig/dest. Distinta")) | O16: =IFERROR(VLOOKUP($I16,Trabajadores!$C$3:$AF$1684,19,FALSE)," ") -> h ASL | P16: 2 | Q16: 9 | R16: =+P16*Q16 -> 18 | T16: =IF(AL16="99100165012016",AQ16,IF(AL16="28009435011996",AR16,IF(AL16="99010825011997",AS16))) -> 1.6367812 | U16: =IF(T16="no corresponde",0,+S16*T16) -> 0 | W16: =+V16*AK16+((+R16+U16)*1.3195) -> 23.751 | X16: =IFERROR(VLOOKUP($I16,Trabajadores!$C$2:$AS$1684,42,FALSE)," ") -> ALGADI | Y16: =IFERROR(VLOOKUP($I16,Trabajadores!$C$2:$AS$1684,40,FALSE)," ") -> 110091 | Z16: =IFERROR(VLOOKUP(Y16,Centros!$X$2:$Y$228,2,FALSE)," ") -> COLEGIO CLARET -MADRID | AA16: 4 y 5 septiembre | AB16: Fallecimiento nieta Berni | AC16: =IFERROR(VLOOKUP(H16,Centros!$AI$2:$AN$10,6,FALSE),0) -> 72 | AD16: =IF(AC16=70,R16,0) -> 0 | AE16: =IF(AC16=72,R16,0) -> 18 | AF16: =IF(AC16=73,+R16,0) -> 0 | AG16: =+U16 -> 0 | AH16: =IFERROR(VLOOKUP($I16,Trabajadores!$C$3:$AT$1684,44,FALSE),0) -> 19228 | AI16: =IFERROR(VLOOKUP($I16,Trabajadores!$C$3:$AT$1684,2,FALSE),0) -> 276 | AJ16: =IFERROR(VLOOKUP($I16,Trabajadores!$C$3:$AY$1270,21,FALSE),0) -> 50 | AK16: =IFERROR(VLOOKUP($I16,Trabajadores!$C$3:$AN$1684,38,FALSE),0) -> 9.47 | AL16: =IFERROR(VLOOKUP($I16,Trabajadores!$C$3:$AN$1684,28,FALSE),0) -> 99100165012016 | AM16: =IFERROR(VLOOKUP($I16,Trabajadores!$C$3:$AN$1684,19,FALSE),0) -> h ASL | AN16: =IFERROR(IF($J16="algadi",VLOOKUP($K16,Centros!$AB$2:$AD$142,2,FALSE),VLOOKUP($K16,Centros!$AB$143:$AD$282,2,FALSE)),0) -> 0 | AO16: =IFERROR(IF($J16="algadi",VLOOKUP($K16,Centros!$AB$2:$AD$142,3,FALSE),VLOOKUP($K16,Centros!$AB$143:$AD$222,3,FALSE)),0) -> 0 | AQ16: =IFERROR(VLOOKUP($AM16,Centros!$AR$2:$AS$405,2,FALSE),0) -> 1.6367812 | AR16: =IFERROR(VLOOKUP($AM16,Centros!$AZ$2:$BA$6,2,FALSE),0) -> 0 | AS16: =IFERROR(VLOOKUP($AM16,Centros!$BE$2:$BF$6,2,FALSE),0) -> 0 | BD16: =+X16 -> ALGADI | BE16: INCIDENCIA | BF16: =+E16 -> 9-SEPTIEMBRE | BG16: =+Y16 -> 110091 | BH16: =VLOOKUP(Y16,Hoja1!$A$2:$O$599,14,FALSE) -> 110091 | BI16: =VLOOKUP(BH16,Hoja1!$A$2:$O$599,2,FALSE) -> COLEGIO CLARET -MADRID | BJ16: =+I16 -> CARRO GUERRERO, M CARMEN | BK16: =VLOOKUP(BJ16,Trabajadores!$C$3:$AN$3285,14,FALSE) -> 300 | BL16: =VLOOKUP($BJ16,Trabajadores!$C$3:$AN$3285,19,FALSE) -> h ASL | BM16: =VLOOKUP($BJ16,Trabajadores!$C$3:$AN$3285,16,FALSE) -> 50 | BN16: =IF($G16="010 Restauración",100%,0%) -> 1 | BO16: =IF($G16="020 Limpieza",100%,0%) -> 0 | BP16: =+BN16+BO16 -> 1 | BR16: =-W16 -> -23.751 | BV16: =+J16 -> ALGADI | BW16: INCIDENCIA | BX16: =+E16 -> 9-SEPTIEMBRE | BY16: =+K16 -> 110091 | BZ16: =VLOOKUP(BY16,Hoja1!$A$2:$O$599,14,FALSE) -> 110091 | CA16: =VLOOKUP(BZ16,Hoja1!$A$2:$O$599,2,FALSE) -> COLEGIO CLARET -MADRID | CB16: =+H16 -> Permiso retribuido | CC16: 888 | CD16: =+BW16 -> INCIDENCIA | CJ16: =+W16 -> 23.751
D17: 945 | E17: 9-SEPTIEMBRE | F17: NO | G17: 010 Restauración | H17: Eventos | I17: CELESTER RODRIGUEZ, ENCARNACIN | J17: ALGADI | K17: 110021 | L17: =IF(W17>0,IF(OR(E17="",F17="",G17="",H17="",I17="",J17="",K17=""),"faltan datos","ok")," ") -> ok | M17: =IFERROR(VLOOKUP(K17,Centros!$E$2:$G$340,2,FALSE)," ") -> COLEGIO FUNDACION CALDEIRO | N17: =IF(J17=" "," ",IF(J17=X17," ","Emp Orig/dest. Distinta")) | O17: =IFERROR(VLOOKUP($I17,Trabajadores!$C$3:$AF$1684,19,FALSE)," ") -> h Cociner@ | P17: 1 | Q17: 11 | R17: =+P17*Q17 -> 11 | T17: =IF(AL17="99100165012016",AQ17,IF(AL17="28009435011996",AR17,IF(AL17="99010825011997",AS17))) -> 1.7437656 | U17: =IF(T17="no corresponde",0,+S17*T17) -> 0 | W17: =+V17*AK17+((+R17+U17)*1.3195) -> 14.5145 | X17: =IFERROR(VLOOKUP($I17,Trabajadores!$C$2:$AS$1684,42,FALSE)," ") -> ALGADI | Y17: =IFERROR(VLOOKUP($I17,Trabajadores!$C$2:$AS$1684,40,FALSE)," ") -> 110021 | Z17: =IFERROR(VLOOKUP(Y17,Centros!$X$2:$Y$228,2,FALSE)," ") -> COLEGIO FUNDACION CALDEIRO | AA17: 45835 | AB17: Evento Caldeiro | AC17: =IFERROR(VLOOKUP(H17,Centros!$AI$2:$AN$10,6,FALSE),0) -> 72 | AD17: =IF(AC17=70,R17,0) -> 0 | AE17: =IF(AC17=72,R17,0) -> 11 | AF17: =IF(AC17=73,+R17,0) -> 0 | AG17: =+U17 -> 0 | AH17: =IFERROR(VLOOKUP($I17,Trabajadores!$C$3:$AT$1684,44,FALSE),0) -> 19228 | AI17: =IFERROR(VLOOKUP($I17,Trabajadores!$C$3:$AT$1684,2,FALSE),0) -> 153 | AJ17: =IFERROR(VLOOKUP($I17,Trabajadores!$C$3:$AY$1270,21,FALSE),0) -> 20 | AK17: =IFERROR(VLOOKUP($I17,Trabajadores!$C$3:$AN$1684,38,FALSE),0) -> 8.68375 | AL17: =IFERROR(VLOOKUP($I17,Trabajadores!$C$3:$AN$1684,28,FALSE),0) -> 99100165012016 | AM17: =IFERROR(VLOOKUP($I17,Trabajadores!$C$3:$AN$1684,19,FALSE),0) -> h Cociner@ | AN17: =IFERROR(IF($J17="algadi",VLOOKUP($K17,Centros!$AB$2:$AD$142,2,FALSE),VLOOKUP($K17,Centros!$AB$143:$AD$282,2,FALSE)),0) -> 19228 | AO17: =IFERROR(IF($J17="algadi",VLOOKUP($K17,Centros!$AB$2:$AD$142,3,FALSE),VLOOKUP($K17,Centros!$AB$143:$AD$222,3,FALSE)),0) -> 20 | AQ17: =IFERROR(VLOOKUP($AM17,Centros!$AR$2:$AS$405,2,FALSE),0) -> 1.7437656 | AR17: =IFERROR(VLOOKUP($AM17,Centros!$AZ$2:$BA$6,2,FALSE),0) -> 0 | AS17: =IFERROR(VLOOKUP($AM17,Centros!$BE$2:$BF$6,2,FALSE),0) -> 0 | BD17: =+X17 -> ALGADI | BE17: INCIDENCIA | BF17: =+E17 -> 9-SEPTIEMBRE | BG17: =+Y17 -> 110021 | BH17: =VLOOKUP(Y17,Hoja1!$A$2:$O$599,14,FALSE) -> 110021 | BI17: =VLOOKUP(BH17,Hoja1!$A$2:$O$599,2,FALSE) -> COLEGIO FUNDACION CALDEIRO | BJ17: =+I17 -> CELESTER RODRIGUEZ, ENCARNACIN | BK17: =VLOOKUP(BJ17,Trabajadores!$C$3:$AN$3285,14,FALSE) -> 100 | BL17: =VLOOKUP($BJ17,Trabajadores!$C$3:$AN$3285,19,FALSE) -> h Cociner@ | BM17: =VLOOKUP($BJ17,Trabajadores!$C$3:$AN$3285,16,FALSE) -> 100 | BN17: =IF($G17="010 Restauración",100%,0%) -> 1 | BO17: =IF($G17="020 Limpieza",100%,0%) -> 0 | BP17: =+BN17+BO17 -> 1 | BR17: =-W17 -> -14.5145 | BV17: =+J17 -> ALGADI | BW17: INCIDENCIA | BX17: =+E17 -> 9-SEPTIEMBRE | BY17: =+K17 -> 110021 | BZ17: =VLOOKUP(BY17,Hoja1!$A$2:$O$599,14,FALSE) -> 110021 | CA17: =VLOOKUP(BZ17,Hoja1!$A$2:$O$599,2,FALSE) -> COLEGIO FUNDACION CALDEIRO | CB17: =+H17 -> Eventos | CC17: 888 | CD17: =+BW17 -> INCIDENCIA | CJ17: =+W17 -> 14.5145
D18: 945 | E18: 9-SEPTIEMBRE | F18: NO | G18: 010 Restauración | H18: Permiso retribuido | I18: CERCAS LORENZO, AURORA B. | J18: ALGADI | K18: 110030 | L18: =IF(W18>0,IF(OR(E18="",F18="",G18="",H18="",I18="",J18="",K18=""),"faltan datos","ok")," ") -> ok | M18: =IFERROR(VLOOKUP(K18,Centros!$E$2:$G$340,2,FALSE)," ") -> COLEGIO INMACULADA | N18: =IF(J18=" "," ",IF(J18=X18," ","Emp Orig/dest. Distinta")) | O18: =IFERROR(VLOOKUP($I18,Trabajadores!$C$3:$AF$1684,19,FALSE)," ") -> h ASL | P18: 1.25 | Q18: 9 | R18: =+P18*Q18 -> 11.25 | T18: =IF(AL18="99100165012016",AQ18,IF(AL18="28009435011996",AR18,IF(AL18="99010825011997",AS18))) -> 1.6367812 | U18: =IF(T18="no corresponde",0,+S18*T18) -> 0 | W18: =+V18*AK18+((+R18+U18)*1.3195) -> 14.844375 | X18: =IFERROR(VLOOKUP($I18,Trabajadores!$C$2:$AS$1684,42,FALSE)," ") -> ALGADI | Y18: =IFERROR(VLOOKUP($I18,Trabajadores!$C$2:$AS$1684,40,FALSE)," ") -> 110030 | Z18: =IFERROR(VLOOKUP(Y18,Centros!$X$2:$Y$228,2,FALSE)," ") -> COLEGIO INMACULADA | AA18: 45905 | AB18: No sustitución de Mildred Mogollón | AC18: =IFERROR(VLOOKUP(H18,Centros!$AI$2:$AN$10,6,FALSE),0) -> 72 | AD18: =IF(AC18=70,R18,0) -> 0 | AE18: =IF(AC18=72,R18,0) -> 11.25 | AF18: =IF(AC18=73,+R18,0) -> 0 | AG18: =+U18 -> 0 | AH18: =IFERROR(VLOOKUP($I18,Trabajadores!$C$3:$AT$1684,44,FALSE),0) -> 19228 | AI18: =IFERROR(VLOOKUP($I18,Trabajadores!$C$3:$AT$1684,2,FALSE),0) -> 202 | AJ18: =IFERROR(VLOOKUP($I18,Trabajadores!$C$3:$AY$1270,21,FALSE),0) -> 36 | AK18: =IFERROR(VLOOKUP($I18,Trabajadores!$C$3:$AN$1684,38,FALSE),0) -> 8.2275 | AL18: =IFERROR(VLOOKUP($I18,Trabajadores!$C$3:$AN$1684,28,FALSE),0) -> 99100165012016 | AM18: =IFERROR(VLOOKUP($I18,Trabajadores!$C$3:$AN$1684,19,FALSE),0) -> h ASL | AN18: =IFERROR(IF($J18="algadi",VLOOKUP($K18,Centros!$AB$2:$AD$142,2,FALSE),VLOOKUP($K18,Centros!$AB$143:$AD$282,2,FALSE)),0) -> 19228 | AO18: =IFERROR(IF($J18="algadi",VLOOKUP($K18,Centros!$AB$2:$AD$142,3,FALSE),VLOOKUP($K18,Centros!$AB$143:$AD$222,3,FALSE)),0) -> 36 | AQ18: =IFERROR(VLOOKUP($AM18,Centros!$AR$2:$AS$405,2,FALSE),0) -> 1.6367812 | AR18: =IFERROR(VLOOKUP($AM18,Centros!$AZ$2:$BA$6,2,FALSE),0) -> 0 | AS18: =IFERROR(VLOOKUP($AM18,Centros!$BE$2:$BF$6,2,FALSE),0) -> 0 | BD18: =+X18 -> ALGADI | BE18: INCIDENCIA | BF18: =+E18 -> 9-SEPTIEMBRE | BG18: =+Y18 -> 110030 | BH18: =VLOOKUP(Y18,Hoja1!$A$2:$O$599,14,FALSE) -> 110030 | BI18: =VLOOKUP(BH18,Hoja1!$A$2:$O$599,2,FALSE) -> COLEGIO INMACULADA | BJ18: =+I18 -> CERCAS LORENZO, AURORA B. | BK18: =VLOOKUP(BJ18,Trabajadores!$C$3:$AN$3285,14,FALSE) -> 300 | BL18: =VLOOKUP($BJ18,Trabajadores!$C$3:$AN$3285,19,FALSE) -> h ASL | BM18: =VLOOKUP($BJ18,Trabajadores!$C$3:$AN$3285,16,FALSE) -> 100 | BN18: =IF($G18="010 Restauración",100%,0%) -> 1 | BO18: =IF($G18="020 Limpieza",100%,0%) -> 0 | BP18: =+BN18+BO18 -> 1 | BR18: =-W18 -> -14.844375 | BV18: =+J18 -> ALGADI | BW18: INCIDENCIA | BX18: =+E18 -> 9-SEPTIEMBRE | BY18: =+K18 -> 110030 | BZ18: =VLOOKUP(BY18,Hoja1!$A$2:$O$599,14,FALSE) -> 110030 | CA18: =VLOOKUP(BZ18,Hoja1!$A$2:$O$599,2,FALSE) -> COLEGIO INMACULADA | CB18: =+H18 -> Permiso retribuido | CC18: 888 | CD18: =+BW18 -> INCIDENCIA | CJ18: =+W18 -> 14.844375
D19: 945 | E19: 9-SEPTIEMBRE | F19: NO | G19: 010 Restauración | H19: Festivos y Fines de Semana | I19: CERCAS LORENZO, AURORA B. | J19: ALGADI | K19: 110030 | L19: =IF(W19>0,IF(OR(E19="",F19="",G19="",H19="",I19="",J19="",K19=""),"faltan datos","ok")," ") -> ok | M19: =IFERROR(VLOOKUP(K19,Centros!$E$2:$G$340,2,FALSE)," ") -> COLEGIO INMACULADA | N19: =IF(J19=" "," ",IF(J19=X19," ","Emp Orig/dest. Distinta")) | O19: =IFERROR(VLOOKUP($I19,Trabajadores!$C$3:$AF$1684,19,FALSE)," ") -> h ASL | P19: 1.25 | Q19: 9 | R19: =+P19*Q19 -> 11.25 | T19: =IF(AL19="99100165012016",AQ19,IF(AL19="28009435011996",AR19,IF(AL19="99010825011997",AS19))) -> 1.6367812 | U19: =IF(T19="no corresponde",0,+S19*T19) -> 0 | W19: =+V19*AK19+((+R19+U19)*1.3195) -> 14.844375 | X19: =IFERROR(VLOOKUP($I19,Trabajadores!$C$2:$AS$1684,42,FALSE)," ") -> ALGADI | Y19: =IFERROR(VLOOKUP($I19,Trabajadores!$C$2:$AS$1684,40,FALSE)," ") -> 110030 | Z19: =IFERROR(VLOOKUP(Y19,Centros!$X$2:$Y$228,2,FALSE)," ") -> COLEGIO INMACULADA | AA19: 45927 | AB19: ASL Sábado comunidad | AC19: =IFERROR(VLOOKUP(H19,Centros!$AI$2:$AN$10,6,FALSE),0) -> 70 | AD19: =IF(AC19=70,R19,0) -> 11.25 | AE19: =IF(AC19=72,R19,0) -> 0 | AF19: =IF(AC19=73,+R19,0) -> 0 | AG19: =+U19 -> 0 | AH19: =IFERROR(VLOOKUP($I19,Trabajadores!$C$3:$AT$1684,44,FALSE),0) -> 19228 | AI19: =IFERROR(VLOOKUP($I19,Trabajadores!$C$3:$AT$1684,2,FALSE),0) -> 202 | AJ19: =IFERROR(VLOOKUP($I19,Trabajadores!$C$3:$AY$1270,21,FALSE),0) -> 36 | AK19: =IFERROR(VLOOKUP($I19,Trabajadores!$C$3:$AN$1684,38,FALSE),0) -> 8.2275 | AL19: =IFERROR(VLOOKUP($I19,Trabajadores!$C$3:$AN$1684,28,FALSE),0) -> 99100165012016 | AM19: =IFERROR(VLOOKUP($I19,Trabajadores!$C$3:$AN$1684,19,FALSE),0) -> h ASL | AN19: =IFERROR(IF($J19="algadi",VLOOKUP($K19,Centros!$AB$2:$AD$142,2,FALSE),VLOOKUP($K19,Centros!$AB$143:$AD$282,2,FALSE)),0) -> 19228 | AO19: =IFERROR(IF($J19="algadi",VLOOKUP($K19,Centros!$AB$2:$AD$142,3,FALSE),VLOOKUP($K19,Centros!$AB$143:$AD$222,3,FALSE)),0) -> 36 | AQ19: =IFERROR(VLOOKUP($AM19,Centros!$AR$2:$AS$405,2,FALSE),0) -> 1.6367812 | AR19: =IFERROR(VLOOKUP($AM19,Centros!$AZ$2:$BA$6,2,FALSE),0) -> 0 | AS19: =IFERROR(VLOOKUP($AM19,Centros!$BE$2:$BF$6,2,FALSE),0) -> 0 | BD19: =+X19 -> ALGADI | BE19: INCIDENCIA | BF19: =+E19 -> 9-SEPTIEMBRE | BG19: =+Y19 -> 110030 | BH19: =VLOOKUP(Y19,Hoja1!$A$2:$O$599,14,FALSE) -> 110030 | BI19: =VLOOKUP(BH19,Hoja1!$A$2:$O$599,2,FALSE) -> COLEGIO INMACULADA | BJ19: =+I19 -> CERCAS LORENZO, AURORA B. | BK19: =VLOOKUP(BJ19,Trabajadores!$C$3:$AN$3285,14,FALSE) -> 300 | BL19: =VLOOKUP($BJ19,Trabajadores!$C$3:$AN$3285,19,FALSE) -> h ASL | BM19: =VLOOKUP($BJ19,Trabajadores!$C$3:$AN$3285,16,FALSE) -> 100 | BN19: =IF($G19="010 Restauración",100%,0%) -> 1 | BO19: =IF($G19="020 Limpieza",100%,0%) -> 0 | BP19: =+BN19+BO19 -> 1 | BR19: =-W19 -> -14.844375 | BV19: =+J19 -> ALGADI | BW19: INCIDENCIA | BX19: =+E19 -> 9-SEPTIEMBRE | BY19: =+K19 -> 110030 | BZ19: =VLOOKUP(BY19,Hoja1!$A$2:$O$599,14,FALSE) -> 110030 | CA19: =VLOOKUP(BZ19,Hoja1!$A$2:$O$599,2,FALSE) -> COLEGIO INMACULADA | CB19: =+H19 -> Festivos y Fines de Semana | CC19: 888 | CD19: =+BW19 -> INCIDENCIA | CJ19: =+W19 -> 14.844375
